The model `gpt3` does not exist
Traceback (most recent call last):
  File "/Users/s22625/repos/pinject-design/pinjected/run_config_utils.py", line 299, in run_anything
    res = design.provide(var)
          ^^^^^^^^^^^^^^^^^^^
  File "/Users/s22625/repos/pinject-design/pinjected/di/util.py", line 335, in provide
    return self.to_graph(modules=modules, classes=classes).provide(target, level=4)
           ^^^^^^^^^^^^^^^^^^^^^^^^^^^^^^^^^^^^^^^^^^^^^^^^^^^^^^^^^^^^^^^^^^^^^^^^
  File "/Users/s22625/repos/pinject-design/pinjected/di/graph.py", line 559, in provide
    res = self.resolver.provide(target, self.scope)
          ^^^^^^^^^^^^^^^^^^^^^^^^^^^^^^^^^^^^^^^^^
  File "/Users/s22625/repos/pinject-design/pinjected/di/graph.py", line 414, in provide
    res = provide_injected(e, key)
          ^^^^^^^^^^^^^^^^^^^^^^^^
  File "/Users/s22625/repos/pinject-design/pinjected/di/graph.py", line 400, in provide_injected
    return scope.provide(key, get_result, trace=[key])
           ^^^^^^^^^^^^^^^^^^^^^^^^^^^^^^^^^^^^^^^^^^^
  File "/Users/s22625/repos/pinject-design/pinjected/di/graph.py", line 228, in provide
    return self.src.provide(key, provider_func, trace)
           ^^^^^^^^^^^^^^^^^^^^^^^^^^^^^^^^^^^^^^^^^^^
  File "/Users/s22625/repos/pinject-design/pinjected/di/graph.py", line 178, in provide
    res = provider()
          ^^^^^^^^^^
  File "/Users/s22625/repos/pinject-design/pinjected/di/graph.py", line 395, in get_result
    raise e
  File "/Users/s22625/repos/pinject-design/pinjected/di/graph.py", line 392, in get_result
    return provider(**kwargs)
           ^^^^^^^^^^^^^^^^^^
  File "<makefun-gen-3>", line 2, in pinjected_di_app_injected_L_17
  File "/Users/s22625/repos/pinject-design/pinjected/di/injected.py", line 535, in impl
    return self.f(tmp)
           ^^^^^^^^^^^
  File "/Users/s22625/repos/pinject-design/pinjected/di/static_proxy.py", line 128, in apply
    return func(*args, **kwargs)
           ^^^^^^^^^^^^^^^^^^^^^
  File "<makefun-gen-27>", line 2, in _injected_partial_greet_to_LLM
  File "/Users/s22625/repos/pinject-design/pinjected/di/injected.py", line 176, in func_gets_called_after_injection_impl
    return original_function(*bind_result.args, **bind_result.kwargs)
           ^^^^^^^^^^^^^^^^^^^^^^^^^^^^^^^^^^^^^^^^^^^^^^^^^^^^^^^^^^
  File "/Users/s22625/repos/pinject-design/pinjected/demo.py", line 22, in greet_to_LLM
    return LLM(f"Kindly respond to the user's message: {user_message}")
           ^^^^^^^^^^^^^^^^^^^^^^^^^^^^^^^^^^^^^^^^^^^^^^^^^^^^^^^^^^^^
  File "<makefun-gen-15>", line 2, in _injected_partial_LLM
  File "/Users/s22625/repos/pinject-design/pinjected/di/injected.py", line 176, in func_gets_called_after_injection_impl
    return original_function(*bind_result.args, **bind_result.kwargs)
           ^^^^^^^^^^^^^^^^^^^^^^^^^^^^^^^^^^^^^^^^^^^^^^^^^^^^^^^^^^
  File "/Users/s22625/repos/pinject-design/pinjected/demo.py", line 17, in LLM
    return openai.Completion.create(openai_api_key, prompt=prompt,model="gpt3")["choices"][0]["text"]
           ^^^^^^^^^^^^^^^^^^^^^^^^^^^^^^^^^^^^^^^^^^^^^^^^^^^^^^^^^^^^^^^^^^^^
  File "/opt/homebrew/Caskroom/miniforge/base/envs/tracking_adain311/lib/python3.11/site-packages/openai/api_resources/completion.py", line 25, in create
    return super().create(*args, **kwargs)
           ^^^^^^^^^^^^^^^^^^^^^^^^^^^^^^^
  File "/opt/homebrew/Caskroom/miniforge/base/envs/tracking_adain311/lib/python3.11/site-packages/openai/api_resources/abstract/engine_api_resource.py", line 153, in create
    response, _, api_key = requestor.request(
                           ^^^^^^^^^^^^^^^^^^
  File "/opt/homebrew/Caskroom/miniforge/base/envs/tracking_adain311/lib/python3.11/site-packages/openai/api_requestor.py", line 298, in request
    resp, got_stream = self._interpret_response(result, stream)
                       ^^^^^^^^^^^^^^^^^^^^^^^^^^^^^^^^^^^^^^^^
  File "/opt/homebrew/Caskroom/miniforge/base/envs/tracking_adain311/lib/python3.11/site-packages/openai/api_requestor.py", line 700, in _interpret_response
    self._interpret_response_line(
  File "/opt/homebrew/Caskroom/miniforge/base/envs/tracking_adain311/lib/python3.11/site-packages/openai/api_requestor.py", line 763, in _interpret_response_line
    raise self.handle_error_response(
openai.error.InvalidRequestError: The model `gpt3` does not exist
